Traceback (most recent call last):
  File "C:\Users\Ollie\anaconda3\Lib\site-packages\jupyter_cache\executors\utils.py", line 58, in single_nb_execution
    executenb(
  File "C:\Users\Ollie\anaconda3\Lib\site-packages\nbclient\client.py", line 1204, in execute
    return NotebookClient(nb=nb, resources=resources, km=km, **kwargs).execute()
           ^^^^^^^^^^^^^^^^^^^^^^^^^^^^^^^^^^^^^^^^^^^^^^^^^^^^^^^^^^^^^^^^^^^^^
  File "C:\Users\Ollie\anaconda3\Lib\site-packages\nbclient\util.py", line 84, in wrapped
    return just_run(coro(*args, **kwargs))
           ^^^^^^^^^^^^^^^^^^^^^^^^^^^^^^^
  File "C:\Users\Ollie\anaconda3\Lib\site-packages\nbclient\util.py", line 62, in just_run
    return loop.run_until_complete(coro)
           ^^^^^^^^^^^^^^^^^^^^^^^^^^^^^
  File "C:\Users\Ollie\anaconda3\Lib\asyncio\base_events.py", line 653, in run_until_complete
    return future.result()
           ^^^^^^^^^^^^^^^
  File "C:\Users\Ollie\anaconda3\Lib\site-packages\nbclient\client.py", line 663, in async_execute
    await self.async_execute_cell(
  File "C:\Users\Ollie\anaconda3\Lib\site-packages\nbclient\client.py", line 965, in async_execute_cell
    await self._check_raise_for_error(cell, cell_index, exec_reply)
  File "C:\Users\Ollie\anaconda3\Lib\site-packages\nbclient\client.py", line 862, in _check_raise_for_error
    raise CellExecutionError.from_cell_and_msg(cell, exec_reply_content)
nbclient.exceptions.CellExecutionError: An error occurred while executing the following cell:
------------------
import pandas as pd
import altair as alt
import numpy as np
from sklearn.model_selection import RandomizedSearchCV
from scipy.stats import loguniform, randint
from sklearn.model_selection import train_test_split, cross_validate
from sklearn.pipeline import make_pipeline
from sklearn.compose import make_column_transformer
from sklearn.preprocessing import StandardScaler, OneHotEncoder, LabelEncoder
from sklearn.impute import SimpleImputer
from sklearn.linear_model import LogisticRegression
from sklearn.metrics import f1_score, accuracy_score, precision_score, recall_score, make_scorer, plot_confusion_matrix
from sklearn.dummy import DummyClassifier
from sklearn.tree import DecisionTreeClassifier, plot_tree, export_text
import matplotlib.pyplot as plt

import plotly.graph_objects as go

------------------

[1;31m---------------------------------------------------------------------------[0m
[1;31mImportError[0m                               Traceback (most recent call last)
Cell [1;32mIn[1], line 12[0m
[0;32m     10[0m [38;5;28;01mfrom[39;00m [38;5;21;01msklearn[39;00m[38;5;21;01m.[39;00m[38;5;21;01mimpute[39;00m [38;5;28;01mimport[39;00m SimpleImputer
[0;32m     11[0m [38;5;28;01mfrom[39;00m [38;5;21;01msklearn[39;00m[38;5;21;01m.[39;00m[38;5;21;01mlinear_model[39;00m [38;5;28;01mimport[39;00m LogisticRegression
[1;32m---> 12[0m [38;5;28;01mfrom[39;00m [38;5;21;01msklearn[39;00m[38;5;21;01m.[39;00m[38;5;21;01mmetrics[39;00m [38;5;28;01mimport[39;00m f1_score, accuracy_score, precision_score, recall_score, make_scorer, plot_confusion_matrix
[0;32m     13[0m [38;5;28;01mfrom[39;00m [38;5;21;01msklearn[39;00m[38;5;21;01m.[39;00m[38;5;21;01mdummy[39;00m [38;5;28;01mimport[39;00m DummyClassifier
[0;32m     14[0m [38;5;28;01mfrom[39;00m [38;5;21;01msklearn[39;00m[38;5;21;01m.[39;00m[38;5;21;01mtree[39;00m [38;5;28;01mimport[39;00m DecisionTreeClassifier, plot_tree, export_text

[1;31mImportError[0m: cannot import name 'plot_confusion_matrix' from 'sklearn.metrics' (C:\Users\Ollie\anaconda3\Lib\site-packages\sklearn\metrics\__init__.py)
ImportError: cannot import name 'plot_confusion_matrix' from 'sklearn.metrics' (C:\Users\Ollie\anaconda3\Lib\site-packages\sklearn\metrics\__init__.py)

